[2025-05-19T13:34:24.444+0000] {logging_mixin.py:188} INFO - Changing /opt/airflow/logs/dag_id=etl_dimensional_model/run_id=manual__2025-05-19T13:34:15.212301+00:00/task_id=populate_dimensional_model permission to 509
[2025-05-19T13:34:24.445+0000] {logging_mixin.py:188} INFO - Failed to change /opt/airflow/logs/dag_id=etl_dimensional_model/run_id=manual__2025-05-19T13:34:15.212301+00:00/task_id=populate_dimensional_model permission to 509: [Errno 1] Operation not permitted: '/opt/airflow/logs/dag_id=etl_dimensional_model/run_id=manual__2025-05-19T13:34:15.212301+00:00/task_id=populate_dimensional_model'
[2025-05-19T13:34:24.464+0000] {logging_mixin.py:188} INFO - Changing /opt/airflow/logs/dag_id=etl_dimensional_model/run_id=manual__2025-05-19T13:34:15.212301+00:00/task_id=populate_dimensional_model permission to 509
[2025-05-19T13:34:24.464+0000] {logging_mixin.py:188} INFO - Failed to change /opt/airflow/logs/dag_id=etl_dimensional_model/run_id=manual__2025-05-19T13:34:15.212301+00:00/task_id=populate_dimensional_model permission to 509: [Errno 1] Operation not permitted: '/opt/airflow/logs/dag_id=etl_dimensional_model/run_id=manual__2025-05-19T13:34:15.212301+00:00/task_id=populate_dimensional_model'
[2025-05-19T13:34:24.491+0000] {taskinstance.py:1957} INFO - Dependencies all met for dep_context=non-requeueable deps ti=<TaskInstance: etl_dimensional_model.populate_dimensional_model manual__2025-05-19T13:34:15.212301+00:00 [queued]>
[2025-05-19T13:34:24.497+0000] {taskinstance.py:1957} INFO - Dependencies all met for dep_context=requeueable deps ti=<TaskInstance: etl_dimensional_model.populate_dimensional_model manual__2025-05-19T13:34:15.212301+00:00 [queued]>
[2025-05-19T13:34:24.497+0000] {taskinstance.py:2171} INFO - Starting attempt 1 of 1
[2025-05-19T13:34:24.506+0000] {taskinstance.py:2192} INFO - Executing <Task(PythonOperator): populate_dimensional_model> on 2025-05-19 13:34:15.212301+00:00
[2025-05-19T13:34:24.511+0000] {standard_task_runner.py:60} INFO - Started process 224 to run task
[2025-05-19T13:34:24.513+0000] {standard_task_runner.py:87} INFO - Running: ['airflow', 'tasks', 'run', 'etl_dimensional_model', 'populate_dimensional_model', 'manual__2025-05-19T13:34:15.212301+00:00', '--job-id', '7', '--raw', '--subdir', 'DAGS_FOLDER/etl_load_postgres_dag.py', '--cfg-path', '/tmp/tmpp6r7nrva']
[2025-05-19T13:34:24.514+0000] {standard_task_runner.py:88} INFO - Job 7: Subtask populate_dimensional_model
[2025-05-19T13:34:24.546+0000] {logging_mixin.py:188} INFO - Changing /opt/airflow/logs/dag_id=etl_dimensional_model/run_id=manual__2025-05-19T13:34:15.212301+00:00/task_id=populate_dimensional_model permission to 509
[2025-05-19T13:34:24.547+0000] {logging_mixin.py:188} INFO - Failed to change /opt/airflow/logs/dag_id=etl_dimensional_model/run_id=manual__2025-05-19T13:34:15.212301+00:00/task_id=populate_dimensional_model permission to 509: [Errno 1] Operation not permitted: '/opt/airflow/logs/dag_id=etl_dimensional_model/run_id=manual__2025-05-19T13:34:15.212301+00:00/task_id=populate_dimensional_model'
[2025-05-19T13:34:24.548+0000] {task_command.py:423} INFO - Running <TaskInstance: etl_dimensional_model.populate_dimensional_model manual__2025-05-19T13:34:15.212301+00:00 [running]> on host f51b95e5a94d
[2025-05-19T13:34:24.697+0000] {taskinstance.py:2481} INFO - Exporting env vars: AIRFLOW_CTX_DAG_OWNER='airflow' AIRFLOW_CTX_DAG_ID='etl_dimensional_model' AIRFLOW_CTX_TASK_ID='populate_dimensional_model' AIRFLOW_CTX_EXECUTION_DATE='2025-05-19T13:34:15.212301+00:00' AIRFLOW_CTX_TRY_NUMBER='1' AIRFLOW_CTX_DAG_RUN_ID='manual__2025-05-19T13:34:15.212301+00:00'
[2025-05-19T13:40:06.125+0000] {local_task_job_runner.py:121} ERROR - Received SIGTERM. Terminating subprocesses
[2025-05-19T13:40:06.128+0000] {process_utils.py:131} INFO - Sending 15 to group 224. PIDs of all processes in the group: [224]
[2025-05-19T13:40:06.129+0000] {process_utils.py:86} INFO - Sending the signal 15 to group 224
[2025-05-19T13:40:06.130+0000] {taskinstance.py:2451} ERROR - Received SIGTERM. Terminating subprocesses.
[2025-05-19T13:40:06.144+0000] {taskinstance.py:2699} ERROR - Task failed with exception
Traceback (most recent call last):
  File "/home/airflow/.local/lib/python3.8/site-packages/airflow/models/taskinstance.py", line 433, in _execute_task
    result = execute_callable(context=context, **execute_callable_kwargs)
  File "/home/airflow/.local/lib/python3.8/site-packages/airflow/operators/python.py", line 199, in execute
    return_value = self.execute_callable()
  File "/home/airflow/.local/lib/python3.8/site-packages/airflow/operators/python.py", line 216, in execute_callable
    return self.python_callable(*self.op_args, **self.op_kwargs)
  File "/opt/airflow/dags/etl_load_postgres_dag.py", line 195, in populate_dimensional_model
    cur.execute("""
  File "/usr/local/lib/python3.8/encodings/utf_8.py", line 15, in decode
    def decode(input, errors='strict'):
  File "/home/airflow/.local/lib/python3.8/site-packages/airflow/models/taskinstance.py", line 2453, in signal_handler
    raise AirflowException("Task received SIGTERM signal")
airflow.exceptions.AirflowException: Task received SIGTERM signal
[2025-05-19T13:40:06.152+0000] {taskinstance.py:1138} INFO - Marking task as FAILED. dag_id=etl_dimensional_model, task_id=populate_dimensional_model, execution_date=20250519T133415, start_date=20250519T133424, end_date=20250519T134006
[2025-05-19T13:40:06.167+0000] {standard_task_runner.py:107} ERROR - Failed to execute job 7 for task populate_dimensional_model (Task received SIGTERM signal; 224)
[2025-05-19T13:40:06.222+0000] {process_utils.py:79} INFO - Process psutil.Process(pid=224, status='terminated', exitcode=1, started='13:34:23') (224) terminated with exit code 1
[2025-05-19T13:40:06.223+0000] {local_task_job_runner.py:234} INFO - Task exited with return code 143
[2025-05-19T13:40:06.238+0000] {taskinstance.py:3281} INFO - 0 downstream tasks scheduled from follow-on schedule check
