[2025-05-16T18:20:21.457+0000] {logging_mixin.py:188} INFO - Changing /opt/airflow/logs/dag_id=etl_dimensional_model/run_id=manual__2025-05-16T18:20:01.710330+00:00/task_id=populate_dimensional_model permission to 509
[2025-05-16T18:20:21.458+0000] {logging_mixin.py:188} INFO - Failed to change /opt/airflow/logs/dag_id=etl_dimensional_model/run_id=manual__2025-05-16T18:20:01.710330+00:00/task_id=populate_dimensional_model permission to 509: [Errno 1] Operation not permitted: '/opt/airflow/logs/dag_id=etl_dimensional_model/run_id=manual__2025-05-16T18:20:01.710330+00:00/task_id=populate_dimensional_model'
[2025-05-16T18:20:21.478+0000] {logging_mixin.py:188} INFO - Changing /opt/airflow/logs/dag_id=etl_dimensional_model/run_id=manual__2025-05-16T18:20:01.710330+00:00/task_id=populate_dimensional_model permission to 509
[2025-05-16T18:20:21.479+0000] {logging_mixin.py:188} INFO - Failed to change /opt/airflow/logs/dag_id=etl_dimensional_model/run_id=manual__2025-05-16T18:20:01.710330+00:00/task_id=populate_dimensional_model permission to 509: [Errno 1] Operation not permitted: '/opt/airflow/logs/dag_id=etl_dimensional_model/run_id=manual__2025-05-16T18:20:01.710330+00:00/task_id=populate_dimensional_model'
[2025-05-16T18:20:21.510+0000] {taskinstance.py:1957} INFO - Dependencies all met for dep_context=non-requeueable deps ti=<TaskInstance: etl_dimensional_model.populate_dimensional_model manual__2025-05-16T18:20:01.710330+00:00 [queued]>
[2025-05-16T18:20:21.517+0000] {taskinstance.py:1957} INFO - Dependencies all met for dep_context=requeueable deps ti=<TaskInstance: etl_dimensional_model.populate_dimensional_model manual__2025-05-16T18:20:01.710330+00:00 [queued]>
[2025-05-16T18:20:21.518+0000] {taskinstance.py:2171} INFO - Starting attempt 1 of 1
[2025-05-16T18:20:21.528+0000] {taskinstance.py:2192} INFO - Executing <Task(PythonOperator): populate_dimensional_model> on 2025-05-16 18:20:01.710330+00:00
[2025-05-16T18:20:21.534+0000] {standard_task_runner.py:60} INFO - Started process 224 to run task
[2025-05-16T18:20:21.536+0000] {standard_task_runner.py:87} INFO - Running: ['airflow', 'tasks', 'run', 'etl_dimensional_model', 'populate_dimensional_model', 'manual__2025-05-16T18:20:01.710330+00:00', '--job-id', '7', '--raw', '--subdir', 'DAGS_FOLDER/etl_load_postgres_dag.py', '--cfg-path', '/tmp/tmphl5mbnmt']
[2025-05-16T18:20:21.537+0000] {standard_task_runner.py:88} INFO - Job 7: Subtask populate_dimensional_model
[2025-05-16T18:20:21.575+0000] {logging_mixin.py:188} INFO - Changing /opt/airflow/logs/dag_id=etl_dimensional_model/run_id=manual__2025-05-16T18:20:01.710330+00:00/task_id=populate_dimensional_model permission to 509
[2025-05-16T18:20:21.575+0000] {logging_mixin.py:188} INFO - Failed to change /opt/airflow/logs/dag_id=etl_dimensional_model/run_id=manual__2025-05-16T18:20:01.710330+00:00/task_id=populate_dimensional_model permission to 509: [Errno 1] Operation not permitted: '/opt/airflow/logs/dag_id=etl_dimensional_model/run_id=manual__2025-05-16T18:20:01.710330+00:00/task_id=populate_dimensional_model'
[2025-05-16T18:20:21.577+0000] {task_command.py:423} INFO - Running <TaskInstance: etl_dimensional_model.populate_dimensional_model manual__2025-05-16T18:20:01.710330+00:00 [running]> on host 5bcdab18d82f
[2025-05-16T18:20:21.747+0000] {taskinstance.py:2481} INFO - Exporting env vars: AIRFLOW_CTX_DAG_OWNER='airflow' AIRFLOW_CTX_DAG_ID='etl_dimensional_model' AIRFLOW_CTX_TASK_ID='populate_dimensional_model' AIRFLOW_CTX_EXECUTION_DATE='2025-05-16T18:20:01.710330+00:00' AIRFLOW_CTX_TRY_NUMBER='1' AIRFLOW_CTX_DAG_RUN_ID='manual__2025-05-16T18:20:01.710330+00:00'
[2025-05-16T18:20:28.060+0000] {taskinstance.py:2699} ERROR - Task failed with exception
Traceback (most recent call last):
  File "/home/airflow/.local/lib/python3.8/site-packages/airflow/models/taskinstance.py", line 433, in _execute_task
    result = execute_callable(context=context, **execute_callable_kwargs)
  File "/home/airflow/.local/lib/python3.8/site-packages/airflow/operators/python.py", line 199, in execute
    return_value = self.execute_callable()
  File "/home/airflow/.local/lib/python3.8/site-packages/airflow/operators/python.py", line 216, in execute_callable
    return self.python_callable(*self.op_args, **self.op_kwargs)
  File "/opt/airflow/dags/etl_load_postgres_dag.py", line 103, in populate_dimensional_model
    cur.execute("""
psycopg2.errors.InvalidTextRepresentation: invalid input syntax for type boolean: "any"
LINE 8:             ) VALUES (80, 'any', 30, 29, 'any', 'any', 'any'...
                                  ^

[2025-05-16T18:20:28.071+0000] {taskinstance.py:1138} INFO - Marking task as FAILED. dag_id=etl_dimensional_model, task_id=populate_dimensional_model, execution_date=20250516T182001, start_date=20250516T182021, end_date=20250516T182028
[2025-05-16T18:20:28.081+0000] {standard_task_runner.py:107} ERROR - Failed to execute job 7 for task populate_dimensional_model (invalid input syntax for type boolean: "any"
LINE 8:             ) VALUES (80, 'any', 30, 29, 'any', 'any', 'any'...
                                  ^
; 224)
[2025-05-16T18:20:28.132+0000] {local_task_job_runner.py:234} INFO - Task exited with return code 1
[2025-05-16T18:20:28.147+0000] {taskinstance.py:3281} INFO - 0 downstream tasks scheduled from follow-on schedule check
